<?xml version="1.0"?>
<robot name="car"  xmlns:xacro="http://ros.org/wiki/xacro">
  <xacro:include filename="$(find car)/urdf/common_properties.xacro"/>
  <xacro:include filename="$(find car)/urdf/car.gazebo.xacro"/>
  <xacro:include filename="$(find car)/urdf/car.trans.xacro"/>
  

  <!-- <link name= "world"/>

  <joint name="fixed" type="fixed">
    <origin xyz="0 0 0" rpy="0 0 0"/>
    <parent link="world"/>
    <child name="base_link"/>
  </joint> -->

  <link name="base_footprint"/>

  <joint name="base_joint" type="fixed">
    <parent link="base_footprint"/>
    <child link="base_link"/>
    <origin xyz="0.0 0.0 0.010" rpy="0 0 0"/>
  </joint>

  <link name="base_link">

    <visual>
      <origin rpy="0.0 0 0" xyz="0 0 0"/>
      <geometry>
        <mesh filename="package://car/meshes/base_link.stl"/>
      </geometry>
      <material name="white"/>
    </visual>

    <collision>
      <origin rpy="0.0 0 0" xyz="0 0 0"/>
      <geometry>
        <mesh filename="package://car/meshes/base_link.stl"/>
      </geometry>
    </collision>

    <inertial>
      <origin
        xyz="0 0 0"
        rpy="0 0 0" />
      <mass
        value="30" />
      <inertia
        ixx="4.5974"
        ixy="0.00011729"
        ixz="-4.2221E-07"
        iyy="12.363"
        iyz="-2.3317E-08"
        izz="12.118" />
    </inertial>
  </link>

  <joint name="rWheelJoint" type="revolute">
    <parent link="base_link"/>
    <axis xyz="1 0 0"/>
    <limit effort="1000.0" lower="-10000000000000000000" upper="10000000000000000000" velocity="3000"/>
    <child link="rWheel"/>
    <origin rpy ="0 0 1.57079" xyz= "-0.515 0.231972 0.044"></origin>
  </joint>

  <link name="rWheel">

    <visual>
      <origin rpy="0 0 0" xyz="0 0 0"/>
      <geometry>
        <mesh filename="package://car/meshes/wheel.stl"/>
      </geometry>
      <material name="black"/>
    </visual>

    <collision>
      <origin rpy="0 1.570795 0" xyz="0 0 0"/>
      <geometry>
        <cylinder length="0.05" radius="0.1"/>
      </geometry>
    </collision>

    <inertial>
      <origin
        xyz="0 0 0"
        rpy="0 0 0" />
      <mass
        value="1" />
      <inertia
        ixx="0.0033492"
        ixy="-2.1115E-09"
        ixz="8.2422E-10"
        iyy="0.0033491"
        iyz="2.1116E-12"
        izz="0.0061933" />
    </inertial>
  </link>

  <joint name="lWheelJoint" type="revolute">
    <parent link="base_link"/>
    <axis xyz="1 0 0"/>
    <limit effort="1000.0" lower="-10000000000000000000" upper="10000000000000000000" velocity="3000"/>
    <child link="lWheel"/>
    <origin rpy ="0 0 1.57079" xyz= "-0.515 -0.231972 0.044"></origin>
  </joint>

  <link name="lWheel">

    <visual>
      <origin rpy="0 0 0" xyz="0 0 0"/>
      <geometry>
        <mesh filename="package://car/meshes/wheel.stl"/>
      </geometry>
      <material name="black"/>
    </visual>

    <collision>
      <origin rpy="0 1.570795 0" xyz="0 0 0"/>
      <geometry>
        <cylinder length="0.05" radius="0.1"/>
      </geometry>
    </collision>
    <inertial>
      <origin
        xyz="0 0 0"
        rpy="0 0 0" />
      <mass
        value="1" />
      <inertia
        ixx="0.0033492"
        ixy="-2.1115E-09"
        ixz="8.2422E-10"
        iyy="0.0033491"
        iyz="2.1116E-12"
        izz="0.0061933" />
    </inertial>
  </link>

  <joint name="steeringJoint" type="revolute">
    <parent link="base_link"/>
    <axis xyz="0 0 1"/>
    <limit effort="1000.0" lower="-10000000000000000000" upper="10000000000000000000" velocity="3000"/>
    <child link="steering"/>
    <origin rpy ="0 0 0" xyz= "0.7242695 0 0.20"></origin>
  </joint>

  <link name="steering">

    <visual>
      <origin rpy="0 0 0" xyz="0 0 0"/>
      <geometry>
        <mesh filename="package://car/meshes/steering.stl"/>
      </geometry>
      <material name="blue"/>
    </visual>

    <collision>
      <origin rpy="0.0 0 0" xyz="0 0 0"/>
      <geometry>
        <mesh filename="package://car/meshes/steering.stl"/>
      </geometry>
    </collision>

    <inertial>
      <origin
        xyz="-3.3084E-06 3.1923E-05 0.084264"
        rpy="0 0 0" />
      <mass
        value="0.33648" />
      <inertia
        ixx="0.0023809"
        ixy="2.2288E-08"
        ixz="-2.8298E-08"
        iyy="0.0022519"
        iyz="3.1939E-07"
        izz="0.00020117" />
    </inertial>
  </link>

  <joint name="fWheelJoint" type="revolute">
    <parent link="steering"/>
    <axis xyz="1 0 0"/>
    <limit effort="1000.0" lower="-10000000000000000000" upper="10000000000000000000" velocity="3000"/>
    <child link="fWheel"/>
    <origin rpy ="0 0 1.57079" xyz= "0 0 -0.185"></origin>
  </joint>

  <link name="fWheel">

    <visual>
      <origin rpy="0 0 0" xyz="0 0 0"/>
      <geometry>
        <mesh filename="package://car/meshes/wheel.stl"/>
        <!-- <sphere radius="0.1"/> -->
      </geometry>
      <material name="black"/>
    </visual>

    <collision>
      <origin rpy="0 1.570795 0" xyz="0 0 0"/>
      <geometry>
        <cylinder length="0.05" radius="0.1"/>
        <!-- <sphere radius="0.1"/> -->
      </geometry>
    </collision>

    <inertial>
      <origin
        xyz="0.035 -1.2831E-06 -5.0403E-08"
        rpy="0 0 0" />
      <mass
        value="1.3795" />
      <inertia
        ixx="0.0061933"
        ixy="2.1116E-12"
        ixz="8.2422E-10"
        iyy="0.0033491"
        iyz="-2.1115E-09"
        izz="0.0033492" />
    </inertial>
  </link>

  <!-- lidar_link -->

  <joint name="laserJoint" type="fixed">
    <parent link="base_link"/>
    <axis xyz="1 0 0"/>
    <limit effort="1000.0" lower="-10000000000000000000" upper="10000000000000000000" velocity="3000"/>
    <child link="hokuyo_lidar"/>
    <origin rpy ="0 0 1.57079" xyz= "0.19 0 0.88"></origin>
  </joint>

  <link name="hokuyo_lidar">

    <visual>
      <origin rpy="0 0 0" xyz="0 0 0"/>
      <geometry>
        <mesh filename="package://car/meshes/lidar.stl"/>
      </geometry>
      <material name="black"/>
    </visual>

    <collision>
      <origin rpy="0 1.570795 0" xyz="0 0 0"/>
      <geometry>
        <mesh filename="package://car/meshes/lidar.stl"/>
      </geometry>
    </collision>

    <inertial>
      <origin
        xyz="0.035 -1.2831E-06 -5.0403E-08"
        rpy="0 0 0" />
      <mass
        value="0.25" />
      <inertia
        ixx="0.0061933"
        ixy="2.1116E-12"
        ixz="8.2422E-10"
        iyy="0.0033491"
        iyz="-2.1115E-09"
        izz="0.0033492" />
    </inertial>
  </link>

  <joint name="cameraJoint" type="fixed">
    <parent link="base_link"/>
    <axis xyz="1 0 0"/>
    <limit effort="1000.0" lower="-10000000000000000000" upper="10000000000000000000" velocity="3000"/>
    <child link="camera"/>
    <origin rpy ="0 0 0" xyz= "0.40 0 0.70"></origin>
  </joint>


  <link name="camera">

    <visual>
      <origin rpy="0 0 0" xyz="0 0 0"/>
      <geometry>
        <mesh filename="package://car/meshes/camera2.stl"/>
      </geometry>
      <material name="black"/>
    </visual>

    <collision>
      <origin rpy="0 1.570795 0" xyz="0 0 0"/>
      <geometry>
        <mesh filename="package://car/meshes/camera2.stl"/>
      </geometry>
    </collision>

    <inertial>
      <origin
        xyz="0.035 -1.2831E-06 -5.0403E-08"
        rpy="0 0 0" />
      <mass
        value="0.25" />
      <inertia
        ixx="0.0061933"
        ixy="2.1116E-12"
        ixz="8.2422E-10"
        iyy="0.0033491"
        iyz="-2.1115E-09"
        izz="0.0033492" />
    </inertial>
  </link>

</robot>
